Workbook

Sheet README
A1: ⚠ SIMULATED FINANCIAL INFORMATION - synthetic demonstration accounts of a fictional retailer, not actual company records. Synthetic data generated for a VisiVault Analytics proof of concept (seed 20240102). Fictional retailer.
A2: Prairie Home Furnishings (fictional) - Integrated Three-Statement Financial Model
A3: Demonstration developed by VisiVault Analytics Ltd. | October 2026
A5: WHAT THIS IS
A6: SIMULATED accounts of a FICTIONAL Calgary furniture retailer, built by double entry from synthetic operational data. Not actual company records.
A7: Historical months (Jan-2024 to Sep-2026) are simulated actuals from the general ledger; Oct-2026 to Sep-2027 are FORECASTS.
A9: HOW TO USE
A10: 1. Assumptions!C4 - choose Conservative / Base / Optimistic / Custom (edit the Custom column freely).
A11: 2. Drivers - edit any blue monthly input (bookings, backlog release, staffing plan, lease, capex plan, inventory cover policy).
A12: 3. Forecast - three statements recalculate; the CHECKS rows and the Checks sheet must stay at 0 / TRUE.
A13: 4. Scenario_Results - stored comparison of the three scenarios and the sensitivity cases.
A15: ACCOUNTING POLICIES
... A25: Assumptions | Drivers | Forecast | Scenario_Results | Checks | Hist_IS | Hist_BS | Hist_CF | Hist_Balances

Sheet Assumptions
A1: ⚠ SIMULATED FINANCIAL INFORMATION - synthetic demonstration accounts of a fictional retailer, not actual company records. Synthetic data generated for a VisiVault Analytics proof of concept (seed 20240102). Fictional retailer.
A2: Forecast assumptions - choose a scenario, or edit the Custom column
A3: Blue cells on yellow are inputs. Column H (Active) feeds every forecast formula.
B4: Active scenario >> | C4: Base
A7: Key | B7: Scenario driver | C7: Unit | D7: Conservative | E7: Base | F7: Optimistic | G7: Custom | H7: Active
A8: volume_change | B8: Sales volume change | C8: % | D8: -0.07 | E8: 0 | F8: 0.05 | G8: 0 | H8: =INDEX(D8:G8,MATCH($C$4,$D$7:$G$7,0)) -> 0
A9: margin_pts | B9: Gross-margin improvement | C9: pts | D9: -0.01 | E9: 0 | F9: 0.02 | G9: 0 | H9: =INDEX(D9:G9,MATCH($C$4,$D$7:$G$7,0)) -> 0
A10: slow_reduction | B10: Slow-moving inventory reduction | C10: % | D10: 0 | E10: 0 | F10: 0.1 | G10: 0 | H10: =INDEX(D10:G10,MATCH($C$4,$D$7:$G$7,0)) -> 0
A11: delay_reduction | B11: Supplier-delay reduction | C11: % | D11: -0.15 | E11: 0 | F11: 0.15 | G11: 0 | H11: =INDEX(D11:G11,MATCH($C$4,$D$7:$G$7,0)) -> 0
A12: consult_conv_change | B12: Design-consultation conversion change | C12: % | D12: 0 | E12: 0 | F12: 0.1 | G12: 0 | H12: =INDEX(D12:G12,MATCH($C$4,$D$7:$G$7,0)) -> 0
A13: dpo_change_days | B13: Change in supplier payment days | C13: days | D13: -5 | E13: 0 | F13: 5 | G13: 0 | H13: =INDEX(D13:G13,MATCH($C$4,$D$7:$G$7,0)) -> 0
A14: opex_change | B14: Change in controllable operating expenses | C14: % | D14: 0.02 | E14: 0 | F14: 0 | G14: 0 | H14: =INDEX(D14:G14,MATCH($C$4,$D$7:$G$7,0)) -> 0
A15: discount_change | B15: Change in promotional discount rate | C15: pts | D15: 0.01 | E15: 0 | F15: 0 | G15: 0 | H15: =INDEX(D15:G15,MATCH($C$4,$D$7:$G$7,0)) -> 0
A16: rate_change | B16: Change in prime rate | C16: % | D16: 0.005 | E16: 0 | F16: 0 | G16: 0 | H16: =INDEX(D16:G16,MATCH($C$4,$D$7:$G$7,0)) -> 0
B18: Scenario notes
B19: Conservative | C19: Bookings -7%, gross margin -1 pt, supplier delays 15% worse, suppliers shorten terms by 5 days, opex +2%, +1 pt promotional discounting, prime +50 bps.
B20: Base | C20: Model A booking forecast, TTM margins, recognition lags, deposit and working-capital ratios, current staffing and lease, prime flat.
B21: Optimistic | C21: Bookings +5%, gross margin +2 pts, 10% of slow-moving stock cleared, supplier delays -15%, consultation conversion +10%, +5 supplier days.
A23: Key | B23: Calibrated / policy parameter (TTM Oct-2025 to Sep-2026 unless stated) | H23: Value
A24: w0 | B24: Share of bookings handed off in the booking month | H24: 0.29289105
A25: w1 | B25: ... 1 month later | H25: 0.25287684
A26: w2 | B26: ... 2 months later | H26: 0.35472419
A27: w3 | B27: ... 3 months later | H27: 0.088573252
A28: w4 | B28: ... 4+ months later | H28: 0.01093467
A29: cancel_rate | B29: Bookings cancelled before hand-off (TTM) | H29: 0.032577667
A30: consult_share | B30: Share of bookings from design consultations | H30: 0.25567061
A31: disc_rate | B31: Discount rate (share of gross sales) | H31: 0.058824344
A32: return_rate | B32: Returns (share of net sales) | H32: 0.0092586302
A33: other_rev_rate | B33: Plan commissions, restocking & cancellation fees (share of net sales) | H33: 0.008983911
A34: cogs_ratio | B34: Merchandise COGS / net furniture sales (TTM) | H34: 0.54681712
A35: freight_ratio | B35: Freight-in / merchandise COGS | H35: 0.041322911
... A65: sbd_limit | B65: Small-business limit | H65: 500000

Sheet Drivers
A1: ⚠ SIMULATED FINANCIAL INFORMATION - synthetic demonstration accounts of a fictional retailer, not actual company records. Synthetic data generated for a VisiVault Analytics proof of concept (seed 20240102). Fictional retailer.
A2: Monthly drivers (inputs) - base volumes from Model 1, staffing plan, lease, marketing plan, capex plan, inventory policy
A3: Edit any blue cell; the forecast recalculates. Column C = actual 30-Sep-2026 position (not used by drivers).
A5: Key | B5: Line | C5: Sep-2026 actual | D5: Oct-2026 | E5: Nov-2026 | F5: Dec-2026 | G5: Jan-2027 | H5: Feb-2027 | I5: Mar-2027 | J5: Apr-2027 | K5: May-2027 | L5: Jun-2027 | M5: Jul-2027 | N5: Aug-2027 | O5: Sep-2027 | P5: 12-month total
A6: bookings_base | B6: Bookings - Model A forecast of written net sales | D6: 856141.99 | E6: 1033083.1 | F6: 775990.39 | G6: 998614.24 | H6: 671138.32 | I6: 934325.68 | J6: 905237.76 | K6: 913017.94 | L6: 801355.72 | M6: 850786.44 | N6: 790309.62 | O6: 871987.17
A7: backlog_release | B7: Opening backlog released (expected hand-off of open orders) | D7: 608564.03 | E7: 358553.69 | F7: 0 | G7: 0 | H7: 0 | I7: 0 | J7: 0 | K7: 0 | L7: 0 | M7: 0 | N7: 0 | O7: 0
A8: payroll_base | B8: Payroll staffing plan (TTM same month +3%, excl. commission) | D8: 123738.21 | E8: 118851.35 | F8: 121062.11 | G8: 127685.45 | H8: 119657.82 | I8: 127823.49 | J8: 123634.18 | K8: 125178.31 | L8: 128358.85 | M8: 127130.69 | N8: 127041.92 | O8: 125897.86
A9: occupancy_d | B9: Occupancy: lease schedule (+3% Jan) + utilities seasonal | D9: 65434.861 | E9: 66270.533 | F9: 67572.806 | G9: 69769.854 | H9: 68636.512 | I9: 67929.374 | J9: 66906.67 | K9: 66449.787 | L9: 64844.934 | M9: 64418.401 | N9: 65150.917 | O9: 65971.501
A10: ga_d | B10: General & administrative (insurance, professional, IT) | D10: 16975.804 | E10: 16226.683 | F10: 17153.621 | G10: 16987.766 | H10: 17182.413 | I10: 16978.059 | J10: 17095.637 | K10: 16987.089 | L10: 17596.185 | M10: 18044.11 | N10: 17900.897 | O10: 18424.559
A11: warehouse_d | B11: Warehouse, fulfilment & design-consult costs | D11: 7201.0862 | E11: 7210.1472 | F11: 6697.555 | G11: 7851.2335 | H11: 7195.3257 | I11: 6525.0475 | J11: 6933.0385 | K11: 7029.5012 | L11: 6764.6003 | M11: 6728.6432 | N11: 7174.262 | O11: 8090.5197
A12: taxable_opex | B12: GST-taxable operating expenses (for ITCs and vendor payables) | D12: 132790.4 | E12: 134227.92 | F12: 133549.73 | G12: 137900.4 | H12: 136659.64 | I12: 113042.92 | J12: 140833.63 | K12: 133705.52 | L12: 125155.37 | M12: 117131.38 | N12: 123025.11 | O12: 132854.8
A13: insurance_exp | B13: Insurance expense | D13: 5624.32 | E13: 5624.32 | F13: 5624.32 | G13: 5849.2928 | H13: 5849.2928 | I13: 5849.2928 | J13: 5849.2928 | K13: 5849.2928 | L13: 5849.2928 | M13: 5849.2928 | N13: 5849.2928 | O13: 5849.2928
A14: insurance_premium | B14: Insurance premium paid (January) | D14: 0 | E14: 0 | F14: 0 | G14: 70191.514 | H14: 0 | I14: 0 | J14: 0 | K14: 0 | L14: 0 | M14: 0 | N14: 0 | O14: 0
A15: capex_d | B15: Capital expenditure plan | D15: 0 | E15: 0 | F15: 0 | G15: 0 | H15: 0 | I15: 40000 | J15: 0 | K15: 0 | L15: 0 | M15: 0 | N15: 0 | O15: 0
A16: da_existing | B16: Depreciation - existing asset register | D16: 6013.09 | E16: 6013.09 | F16: 6013.09 | G16: 6013.09 | H16: 6013.09 | I16: 6013.09 | J16: 6013.09 | K16: 6013.09 | L16: 6013.09 | M16: 6013.09 | N16: 6013.09 | O16: 6013.09
A17: cover_k | B17: Stocked inventory: months of forward cover (seasonal, from history) | D17: 1.7901008 | E17: 1.5133345 | F17: 1.7821513 | G17: 1.8669478 | H17: 2.0302214 | I17: 2.0531654 | J17: 1.9378534 | K17: 1.8692052 | L17: 1.9202687 | M17: 1.9128635 | N17: 2.2328019 | O17: 1.9403401
... A23: q_start | B23: Flag: first month of quarter | D23: 1 | E23: 0 | F23: 0 | G23: 1 | H23: 0 | I23: 0 | J23: 1 | K23: 0 | L23: 0 | M23: 1 | N23: 0 | O23: 0

Sheet Forecast
A1: ⚠ SIMULATED FINANCIAL INFORMATION - synthetic demonstration accounts of a fictional retailer, not actual company records. Synthetic data generated for a VisiVault Analytics proof of concept (seed 20240102). Fictional retailer.
A2: Integrated 12-month forecast Oct-2026 to Sep-2027 (FORECAST - not historical fact)
A3: Every cell in columns D:O is a formula driven by Assumptions (active scenario) and Drivers. Column C links to the historical ledger.
A5: Key | B5: Line | C5: Sep-2026 actual | D5: Oct-2026 | E5: Nov-2026 | F5: Dec-2026 | G5: Jan-2027 | H5: Feb-2027 | I5: Mar-2027 | J5: Apr-2027 | K5: May-2027 | L5: Jun-2027 | M5: Jul-2027 | N5: Aug-2027 | O5: Sep-2027 | P5: 12-month total
A7: INCOME STATEMENT (forecast)
A8: gross_sales | B8: Gross furniture sales | D8: =D11/(1-Assumptions!$H$31-Assumptions!$H$15)/(1-Assumptions!$H$32) -> 891538.75 | E8: =E11/(1-Assumptions!$H$31-Assumptions!$H$15)/(1-Assumptions!$H$32) -> 910537.94 | F8: =F11/(1-Assumptions!$H$31-Assumptions!$H$15)/(1-Assumptions!$H$32) -> 821920.22 | G8: =G11/(1-Assumptions!$H$31-Assumptions!$H$15)/(1-Assumptions!$H$32) -> 965912.1 | H8: =H11/(1-Assumptions!$H$31-Assumptions!$H$15)/(1-Assumptions!$H$32) -> 856164.59 | I8: =I11/(1-Assumptions!$H$31-Assumptions!$H$15)/(1-Assumptions!$H$32) -> 910536.96 | J8: =J11/(1-Assumptions!$H$31-Assumptions!$H$15)/(1-Assumptions!$H$32) -> 867769.49 | K8: =K11/(1-Assumptions!$H$31-Assumptions!$H$15)/(1-Assumptions!$H$32) -> 931793.92 | ... O8: =O11/(1-Assumptions!$H$31-Assumptions!$H$15)/(1-Assumptions!$H$32) -> 869424.22 | P8: =SUM(D8:O8) -> 10686290
A9: discounts | B9: Less: discounts & promotional allowances | D9: =-D8*(Assumptions!$H$31+Assumptions!$H$15) -> -52444.183 | E9: =-E8*(Assumptions!$H$31+Assumptions!$H$15) -> -53561.798 | F9: =-F8*(Assumptions!$H$31+Assumptions!$H$15) -> -48348.918 | G9: =-G8*(Assumptions!$H$31+Assumptions!$H$15) -> -56819.146 | H9: =-H8*(Assumptions!$H$31+Assumptions!$H$15) -> -50363.321 | I9: =-I8*(Assumptions!$H$31+Assumptions!$H$15) -> -53561.74 | J9: =-J8*(Assumptions!$H$31+Assumptions!$H$15) -> -51045.972 | K9: =-K8*(Assumptions!$H$31+Assumptions!$H$15) -> -54812.167 | ... O9: =-O8*(Assumptions!$H$31+Assumptions!$H$15) -> -51143.31 | P9: =SUM(D9:O9) -> -628614.03
A10: returns | B10: Less: sales returns | D10: =D11-D8-D9 -> -7768.8663 | E10: =E11-E8-E9 -> -7934.4252 | F10: =F11-F8-F9 -> -7162.2106 | G10: =G11-G8-G9 -> -8416.9555 | H10: =H11-H8-H9 -> -7460.616 | I10: =I11-I8-I9 -> -7934.4167 | J10: =J11-J8-J9 -> -7561.7411 | K10: =K11-K8-K9 -> -8119.6498 | ... O10: =O11-O8-O9 -> -7576.1604 | P10: =SUM(D10:O10) -> -93120.306
A11: net_sales | B11: Net furniture sales (recognised at hand-off) | D11: =(Drivers!D7+Assumptions!$H$24*D85+D86*C85+D87*0+D88*0+D89*0)*(1-D90) -> 831325.7 | E11: =(Drivers!E7+Assumptions!$H$24*E85+E86*D85+E87*C85+E88*0+E89*0)*(1-E90) -> 849041.72 | F11: =(Drivers!F7+Assumptions!$H$24*F85+F86*E85+F87*D85+F88*C85+F89*0)*(1-F90) -> 766409.09 | G11: =(Drivers!G7+Assumptions!$H$24*G85+G86*F85+G87*E85+G88*D85+G89*C85)*(1-G90) -> 900676 | H11: =(Drivers!H7+Assumptions!$H$24*H85+H86*G85+H87*F85+H88*E85+H89*D85)*(1-H90) -> 798340.65 | I11: =(Drivers!I7+Assumptions!$H$24*I85+I86*H85+I87*G85+I88*F85+I89*E85)*(1-I90) -> 849040.81 | J11: =(Drivers!J7+Assumptions!$H$24*J85+J86*I85+J87*H85+J88*G85+J89*F85)*(1-J90) -> 809161.78 | K11: =(Drivers!K7+Assumptions!$H$24*K85+K86*J85+K87*I85+K88*H85+K89*G85)*(1-K90) -> 868862.11 | L11: =(Drivers!L7+Assumptions!$H$24*L85+L86*K85+L87*J85+L88*I85+L89*H85)*(1-L90) -> 848231.72 | M11: =(Drivers!M7+Assumptions!$H$24*M85+M86*L85+M87*K85+M88*J85+M89*I85)*(1-M90) -> 837882.53 | N11: =(Drivers!N7+Assumptions!$H$24*N85+N86*M85+N87*L85+N88*K85+N89*J85)*(1-N90) -> 794879.18 | O11: =(Drivers!O7+Assumptions!$H$24*O85+O86*N85+O87*M85+O88*L85+O89*K85)*(1-O90) -> 810704.75 | P11: =SUM(D11:O11) -> 9964556
A12: other_rev | B12: Plan commissions, restocking & cancellation fees | D12: =Assumptions!$H$33*D11 -> 7468.5561 | E12: =Assumptions!$H$33*E11 -> 7627.7152 | F12: =Assumptions!$H$33*F11 -> 6885.351 | G12: =Assumptions!$H$33*G11 -> 8091.593 | H12: =Assumptions!$H$33*H11 -> 7172.2213 | I12: =Assumptions!$H$33*I11 -> 7627.707 | J12: =Assumptions!$H$33*J11 -> 7269.4374 | K12: =Assumptions!$H$33*K11 -> 7805.7798 | ... O12: =Assumptions!$H$33*O11 -> 7283.2993 | P12: =SUM(D12:O12) -> 89520.684
A13: net_rev | B13: Total net revenue | D13: =D11+D12 -> 838794.26 | E13: =E11+E12 -> 856669.43 | F13: =F11+F12 -> 773294.44 | G13: =G11+G12 -> 908767.59 | H13: =H11+H12 -> 805512.87 | I13: =I11+I12 -> 856668.51 | J13: =J11+J12 -> 816431.22 | K13: =K11+K12 -> 876667.89 | ... O13: =O11+O12 -> 817988.05 | P13: =SUM(D13:O13) -> 10054077
A14: cogs_merch | B14: Cost of goods sold - merchandise | D14: =-D11*(Assumptions!$H$34-Assumptions!$H$9) -> -454583.13 | E14: =-E11*(Assumptions!$H$34-Assumptions!$H$9) -> -464270.55 | F14: =-F11*(Assumptions!$H$34-Assumptions!$H$9) -> -419085.61 | G14: =-G11*(Assumptions!$H$34-Assumptions!$H$9) -> -492505.06 | H14: =-H11*(Assumptions!$H$34-Assumptions!$H$9) -> -436546.34 | I14: =-I11*(Assumptions!$H$34-Assumptions!$H$9) -> -464270.05 | J14: =-J11*(Assumptions!$H$34-Assumptions!$H$9) -> -442463.52 | K14: =-K11*(Assumptions!$H$34-Assumptions!$H$9) -> -475108.68 | ... O14: =-O11*(Assumptions!$H$34-Assumptions!$H$9) -> -443307.24 | P14: =SUM(D14:O14) -> -5448789.8
A15: freight_in | B15: Freight-in & supplier charges | D15: =D14*Assumptions!$H$35 -> -18784.698 | E15: =E14*Assumptions!$H$35 -> -19185.01 | F15: =F14*Assumptions!$H$35 -> -17317.837 | G15: =G14*Assumptions!$H$35 -> -20351.742 | H15: =H14*Assumptions!$H$35 -> -18039.365 | I15: =I14*Assumptions!$H$35 -> -19184.99 | J15: =J14*Assumptions!$H$35 -> -18283.88 | K15: =K14*Assumptions!$H$35 -> -19632.873 | ... O15: =O14*Assumptions!$H$35 -> -18318.745 | P15: =SUM(D15:O15) -> -225159.86
A16: inv_var | B16: Inventory variances & markdowns | D16: =D14*Assumptions!$H$36-Drivers!D19*Assumptions!$H$10*Assumptions!$H$60*Assumptions!$H$61 -> -4841.7749 | E16: =E14*Assumptions!$H$36-Drivers!E19*Assumptions!$H$10*Assumptions!$H$60*Assumptions!$H$61 -> -4944.9559 | F16: =F14*Assumptions!$H$36-Drivers!F19*Assumptions!$H$10*Assumptions!$H$60*Assumptions!$H$61 -> -4463.6901 | G16: =G14*Assumptions!$H$36-Drivers!G19*Assumptions!$H$10*Assumptions!$H$60*Assumptions!$H$61 -> -5245.6822 | H16: =H14*Assumptions!$H$36-Drivers!H19*Assumptions!$H$10*Assumptions!$H$60*Assumptions!$H$61 -> -4649.6647 | I16: =I14*Assumptions!$H$36-Drivers!I19*Assumptions!$H$10*Assumptions!$H$60*Assumptions!$H$61 -> -4944.9505 | J16: =J14*Assumptions!$H$36-Drivers!J19*Assumptions!$H$10*Assumptions!$H$60*Assumptions!$H$61 -> -4712.6887 | K16: =K14*Assumptions!$H$36-Drivers!K19*Assumptions!$H$10*Assumptions!$H$60*Assumptions!$H$61 -> -5060.393 | ... O16: =O14*Assumptions!$H$36-Drivers!O19*Assumptions!$H$10*Assumptions!$H$60*Assumptions!$H$61 -> -4721.6752 | P16: =SUM(D16:O16) -> -58035.181
A17: cogs | B17: Cost of goods sold | D17: =D14+D15+D16 -> -478209.6 | E17: =E14+E15+E16 -> -488400.52 | F17: =F14+F15+F16 -> -440867.14 | G17: =G14+G15+G16 -> -518102.48 | H17: =H14+H15+H16 -> -459235.37 | I17: =I14+I15+I16 -> -488399.99 | J17: =J14+J15+J16 -> -465460.08 | K17: =K14+K15+K16 -> -499801.94 | ... O17: =O14+O15+O16 -> -466347.66 | P17: =SUM(D17:O17) -> -5731984.9
A18: gross_profit | B18: Gross profit | D18: =D13+D17 -> 360584.66 | E18: =E13+E17 -> 368268.92 | F18: =F13+F17 -> 332427.3 | G18: =G13+G17 -> 390665.11 | H18: =H13+H17 -> 346277.51 | I18: =I13+I17 -> 368268.52 | J18: =J13+J17 -> 350971.13 | K18: =K13+K17 -> 376865.94 | ... O18: =O13+O17 -> 351640.39 | P18: =SUM(D18:O18) -> 4322091.8
A19: emp_comp | B19: Employee compensation | D19: =-D94 -> -138103.47 | E19: =-E94 -> -136185.52 | F19: =-F94 -> -134082.51 | G19: =-G94 -> -144441.27 | H19: =-H94 -> -130918.9 | I19: =-I94 -> -143500.61 | J19: =-J94 -> -138823.22 | K19: =-K94 -> -140497.9 | ... O19: =-O94 -> -140528.99 | P19: =SUM(D19:O19) -> -1670595.9
A20: occupancy | B20: Occupancy (lease schedule, utilities) | D20: =-Drivers!D9 -> -65434.861 | E20: =-Drivers!E9 -> -66270.533 | F20: =-Drivers!F9 -> -67572.806 | G20: =-Drivers!G9 -> -69769.854 | H20: =-Drivers!H9 -> -68636.512 | I20: =-Drivers!I9 -> -67929.374 | J20: =-Drivers!J9 -> -66906.67 | K20: =-Drivers!K9 -> -66449.787 | ... O20: =-Drivers!O9 -> -65971.501 | P20: =SUM(D20:O20) -> -799356.15
A21: marketing | B21: Marketing & advertising | D21: =-Assumptions!$H$39*IF(Drivers!D19,Drivers!D18,C85)*(1+Assumptions!$H$14) -> -43726.153 | E21: =-Assumptions!$H$39*IF(Drivers!E19,Drivers!E18,D85)*(1+Assumptions!$H$14) -> -42912.337 | F21: =-Assumptions!$H$39*IF(Drivers!F19,Drivers!F18,E85)*(1+Assumptions!$H$14) -> -51781.14 | G21: =-Assumptions!$H$39*IF(Drivers!G19,Drivers!G18,F85)*(1+Assumptions!$H$14) -> -38894.904 | H21: =-Assumptions!$H$39*IF(Drivers!H19,Drivers!H18,G85)*(1+Assumptions!$H$14) -> -50053.462 | I21: =-Assumptions!$H$39*IF(Drivers!I19,Drivers!I18,H85)*(1+Assumptions!$H$14) -> -33639.413 | J21: =-Assumptions!$H$39*IF(Drivers!J19,Drivers!J18,I85)*(1+Assumptions!$H$14) -> -46831.132 | K21: =-Assumptions!$H$39*IF(Drivers!K19,Drivers!K18,J85)*(1+Assumptions!$H$14) -> -45373.16 | ... O21: =-Assumptions!$H$39*IF(Drivers!O19,Drivers!O18,N85)*(1+Assumptions!$H$14) -> -39612.626 | P21: =SUM(D21:O21) -> -521397.64
A22: g_and_a | B22: General & administrative | D22: =-Drivers!D10*(1+Assumptions!$H$14) -> -16975.804 | E22: =-Drivers!E10*(1+Assumptions!$H$14) -> -16226.683 | F22: =-Drivers!F10*(1+Assumptions!$H$14) -> -17153.621 | G22: =-Drivers!G10*(1+Assumptions!$H$14) -> -16987.766 | H22: =-Drivers!H10*(1+Assumptions!$H$14) -> -17182.413 | I22: =-Drivers!I10*(1+Assumptions!$H$14) -> -16978.059 | J22: =-Drivers!J10*(1+Assumptions!$H$14) -> -17095.637 | K22: =-Drivers!K10*(1+Assumptions!$H$14) -> -16987.089 | ... O22: =-Drivers!O10*(1+Assumptions!$H$14) -> -18424.559 | P22: =SUM(D22:O22) -> -207552.82
A23: warehouse | B23: Warehouse, fulfilment & design-consult costs | D23: =-Drivers!D11*(1+Assumptions!$H$14) -> -7201.0862 | E23: =-Drivers!E11*(1+Assumptions!$H$14) -> -7210.1472 | F23: =-Drivers!F11*(1+Assumptions!$H$14) -> -6697.555 | G23: =-Drivers!G11*(1+Assumptions!$H$14) -> -7851.2335 | H23: =-Drivers!H11*(1+Assumptions!$H$14) -> -7195.3257 | I23: =-Drivers!I11*(1+Assumptions!$H$14) -> -6525.0475 | J23: =-Drivers!J11*(1+Assumptions!$H$14) -> -6933.0385 | K23: =-Drivers!K11*(1+Assumptions!$H$14) -> -7029.5012 | ... O23: =-Drivers!O11*(1+Assumptions!$H$14) -> -8090.5197 | P23: =SUM(D23:O23) -> -85400.96
A24: fees | B24: Card & financing-partner fees | D24: =-Assumptions!$H$40*D13 -> -20059.075 | E24: =-Assumptions!$H$40*E13 -> -20486.545 | F24: =-Assumptions!$H$40*F13 -> -18492.7 | G24: =-Assumptions!$H$40*G13 -> -21732.429 | H24: =-Assumptions!$H$40*H13 -> -19263.178 | I24: =-Assumptions!$H$40*I13 -> -20486.523 | J24: =-Assumptions!$H$40*J13 -> -19524.281 | K24: =-Assumptions!$H$40*K13 -> -20964.791 | ... O24: =-Assumptions!$H$40*O13 -> -19561.511 | P24: =SUM(D24:O24) -> -240434.97
A25: opex | B25: Operating expenses (before depreciation) | D25: =D19+D20+D21+D22+D23+D24 -> -291500.45 | E25: =E19+E20+E21+E22+E23+E24 -> -289291.77 | F25: =F19+F20+F21+F22+F23+F24 -> -295780.33 | G25: =G19+G20+G21+G22+G23+G24 -> -299677.46 | H25: =H19+H20+H21+H22+H23+H24 -> -293249.79 | I25: =I19+I20+I21+I22+I23+I24 -> -289059.03 | J25: =J19+J20+J21+J22+J23+J24 -> -296113.98 | K25: =K19+K20+K21+K22+K23+K24 -> -297302.23 | ... O25: =O19+O20+O21+O22+O23+O24 -> -292189.71 | P25: =SUM(D25:O25) -> -3524738.5
A26: ebitda | B26: EBITDA | D26: =D18+D25 -> 69084.207 | E26: =E18+E25 -> 78977.151 | F26: =F18+F25 -> 36646.97 | G26: =G18+G25 -> 90987.649 | H26: =H18+H25 -> 53027.718 | I26: =I18+I25 -> 79209.495 | J26: =J18+J25 -> 54857.151 | K26: =K18+K25 -> 79563.712 | ... O26: =O18+O25 -> 59450.681 | P26: =SUM(D26:O26) -> 797353.35
A27: da | B27: Depreciation | D27: =-(Drivers!D16+C97/Assumptions!$H$62) -> -6013.09 | E27: =-(Drivers!E16+D97/Assumptions!$H$62) -> -6013.09 | F27: =-(Drivers!F16+E97/Assumptions!$H$62) -> -6013.09 | G27: =-(Drivers!G16+F97/Assumptions!$H$62) -> -6013.09 | H27: =-(Drivers!H16+G97/Assumptions!$H$62) -> -6013.09 | I27: =-(Drivers!I16+H97/Assumptions!$H$62) -> -6013.09 | J27: =-(Drivers!J16+I97/Assumptions!$H$62) -> -6489.2805 | K27: =-(Drivers!K16+J97/Assumptions!$H$62) -> -6489.2805 | ... O27: =-(Drivers!O16+N97/Assumptions!$H$62) -> -6489.2805 | P27: =SUM(D27:O27) -> -75014.223
A28: ebit | B28: Operating income (EBIT) | D28: =D26+D27 -> 63071.117 | E28: =E26+E27 -> 72964.061 | F28: =F26+F27 -> 30633.88 | G28: =G26+G27 -> 84974.559 | H28: =H26+H27 -> 47014.628 | I28: =I26+I27 -> 73196.405 | J28: =J26+J27 -> 48367.87 | K28: =K26+K27 -> 73074.431 | ... O28: =O26+O27 -> 52961.401 | P28: =SUM(D28:O28) -> 722339.13
A29: interest | B29: Interest expense | D29: =-(C104*(Assumptions!$H$49+Assumptions!$H$16+Assumptions!$H$50)+C52*(Assumptions!$H$49+Assumptions!$H$16+Assumptions!$H$51))/12 -> -839.84316 | E29: =-(D104*(Assumptions!$H$49+Assumptions!$H$16+Assumptions!$H$50)+D52*(Assumptions!$H$49+Assumptions!$H$16+Assumptions!$H$51))/12 -> -783.85356 | F29: =-(E104*(Assumptions!$H$49+Assumptions!$H$16+Assumptions!$H$50)+E52*(Assumptions!$H$49+Assumptions!$H$16+Assumptions!$H$51))/12 -> -727.86396 | G29: =-(F104*(Assumptions!$H$49+Assumptions!$H$16+Assumptions!$H$50)+F52*(Assumptions!$H$49+Assumptions!$H$16+Assumptions!$H$51))/12 -> -671.87436 | H29: =-(G104*(Assumptions!$H$49+Assumptions!$H$16+Assumptions!$H$50)+G52*(Assumptions!$H$49+Assumptions!$H$16+Assumptions!$H$51))/12 -> -615.88475 | I29: =-(H104*(Assumptions!$H$49+Assumptions!$H$16+Assumptions!$H$50)+H52*(Assumptions!$H$49+Assumptions!$H$16+Assumptions!$H$51))/12 -> -559.89515 | J29: =-(I104*(Assumptions!$H$49+Assumptions!$H$16+Assumptions!$H$50)+I52*(Assumptions!$H$49+Assumptions!$H$16+Assumptions!$H$51))/12 -> -503.90555 | K29: =-(J104*(Assumptions!$H$49+Assumptions!$H$16+Assumptions!$H$50)+J52*(Assumptions!$H$49+Assumptions!$H$16+Assumptions!$H$51))/12 -> -447.91595 | ... O29: =-(N104*(Assumptions!$H$49+Assumptions!$H$16+Assumptions!$H$50)+N52*(Assumptions!$H$49+Assumptions!$H$16+Assumptions!$H$51))/12 -> -223.95755 | P29: =SUM(D29:O29) -> -6382.8042
A30: pbt | B30: Income before tax | D30: =D28+D29 -> 62231.274 | E30: =E28+E29 -> 72180.207 | F30: =F28+F29 -> 29906.016 | G30: =G28+G29 -> 84302.685 | H30: =H28+H29 -> 46398.743 | I30: =I28+I29 -> 72636.51 | J30: =J28+J29 -> 47863.965 | K30: =K28+K29 -> 72626.515 | ... O30: =O28+O29 -> 52737.443 | P30: =SUM(D30:O30) -> 715956.32
A31: tax | B31: Income taxes | D31: =-(D109-IF(Drivers!D20,0,C109)) -> -14313.197 | E31: =-(E109-IF(Drivers!E20,0,D109)) -> -16601.448 | F31: =-(F109-IF(Drivers!F20,0,E109)) -> -6878.3838 | G31: =-(G109-IF(Drivers!G20,0,F109)) -> -9273.2953 | H31: =-(H109-IF(Drivers!H20,0,G109)) -> -5103.8618 | I31: =-(I109-IF(Drivers!I20,0,H109)) -> -7990.0161 | J31: =-(J109-IF(Drivers!J20,0,I109)) -> -5265.0361 | K31: =-(K109-IF(Drivers!K20,0,J109)) -> -7988.9167 | ... O31: =-(O109-IF(Drivers!O20,0,N109)) -> -11997.778 | P31: =SUM(D31:O31) -> -104669.96
A32: net_income | B32: Net income | D32: =D30+D31 -> 47918.077 | E32: =E30+E31 -> 55578.76 | F32: =F30+F31 -> 23027.633 | G32: =G30+G31 -> 75029.389 | H32: =H30+H31 -> 41294.881 | I32: =I30+I31 -> 64646.494 | J32: =J30+J31 -> 42598.929 | K32: =K30+K31 -> 64637.599 | ... O32: =O30+O31 -> 40739.665 | P32: =SUM(D32:O32) -> 611286.36
A34: BALANCE SHEET (forecast; column C = actual 30-Sep-2026 from the general ledger)
A35: cash | B35: Cash | C35: =Hist_Balances!$AJ$6 -> 1722169.8 | D35: =C35+D78 -> 1888904.5 | E35: =D35+E78 -> 2008660.8 | F35: =E35+F78 -> 1680881 | G35: =F35+G78 -> 1696031.7 | H35: =G35+H78 -> 1584646 | I35: =H35+I78 -> 1520292.6 | J35: =I35+J78 -> 1563027.4 | K35: =J35+K78 -> 1681278.9 | ... O35: =N35+O78 -> 1812609.1
A36: ar | B36: Receivables | C36: =Hist_Balances!$AJ$7+Hist_Balances!$AJ$8+Hist_Balances!$AJ$9 -> 73595.1 | D36: =Assumptions!$H$43*D13*(1+Assumptions!$H$48) -> 87796.624 | E36: =Assumptions!$H$43*E13*(1+Assumptions!$H$48) -> 89667.619 | F36: =Assumptions!$H$43*F13*(1+Assumptions!$H$48) -> 80940.756 | G36: =Assumptions!$H$43*G13*(1+Assumptions!$H$48) -> 95120.735 | H36: =Assumptions!$H$43*H13*(1+Assumptions!$H$48) -> 84313.06 | I36: =Assumptions!$H$43*I13*(1+Assumptions!$H$48) -> 89667.523 | J36: =Assumptions!$H$43*J13*(1+Assumptions!$H$48) -> 85455.884 | K36: =Assumptions!$H$43*K13*(1+Assumptions!$H$48) -> 91760.858 | ... O36: =Assumptions!$H$43*O13*(1+Assumptions!$H$48) -> 85618.838
A37: inv_stock | B37: Inventory - stocked merchandise | C37: =Hist_Balances!$AJ$10 -> 505080.18 | D37: =C37+D96-(D38-C38)+D14+D16 -> 555488.5 | E37: =D37+E96-(E38-D38)+E14+E16 -> 484614.66 | F37: =E37+F96-(F38-E38)+F14+F16 -> 581629 | G37: =F37+G96-(G38-F38)+G14+G16 -> 590785.99 | H37: =G37+H96-(H38-G38)+H14+H16 -> 646673.16 | I37: =H37+I96-(I38-H38)+I14+I16 -> 661798.73 | J37: =I37+J96-(J38-I38)+J14+J16 -> 639173.54 | K37: =J37+K96-(K38-J38)+K14+K16 -> 605407.53 | ... O37: =N37+O96-(O38-N38)+O14+O16 -> 626305.12
A38: inv_alloc | B38: Inventory - allocated to customer orders | C38: =Hist_Balances!$AJ$11 -> 279846.23 | D38: =Assumptions!$H$42*D48 -> 278582.38 | E38: =Assumptions!$H$42*E48 -> 323508.09 | F38: =Assumptions!$H$42*F48 -> 318818.34 | G38: =Assumptions!$H$42*G48 -> 338357.39 | H38: =Assumptions!$H$42*H48 -> 293825.85 | I38: =Assumptions!$H$42*I48 -> 310210.55 | J38: =Assumptions!$H$42*J48 -> 330102.03 | K38: =Assumptions!$H$42*K48 -> 334407.37 | ... O38: =Assumptions!$H$42*O48 -> 308944.32
A39: prepaid | B39: Prepaid expenses | C39: =Hist_Balances!$AJ$12 -> 16872.96 | D39: =C39+Drivers!D14-Drivers!D13 -> 11248.64 | E39: =D39+Drivers!E14-Drivers!E13 -> 5624.32 | F39: =E39+Drivers!F14-Drivers!F13 -> 0 | G39: =F39+Drivers!G14-Drivers!G13 -> 64342.221 | H39: =G39+Drivers!H14-Drivers!H13 -> 58492.928 | I39: =H39+Drivers!I14-Drivers!I13 -> 52643.635 | J39: =I39+Drivers!J14-Drivers!J13 -> 46794.342 | K39: =J39+Drivers!K14-Drivers!K13 -> 40945.05 | ... O39: =N39+Drivers!O14-Drivers!O13 -> 17547.878
A40: gst_rec | B40: GST recoverable | C40: =Hist_BS!$AI$11 -> 0 | D40: =MAX(0,-D100) -> 0 | E40: =MAX(0,-E100) -> 0 | F40: =MAX(0,-F100) -> 0 | G40: =MAX(0,-G100) -> 0 | H40: =MAX(0,-H100) -> 0 | I40: =MAX(0,-I100) -> 0 | J40: =MAX(0,-J100) -> 0 | K40: =MAX(0,-K100) -> 0 | ... O40: =MAX(0,-O100) -> 0
A41: current_assets | B41: Total current assets | C41: =Hist_BS!$AI$12 -> 2597564.2 | D41: =D35+D36+D37+D38+D39+D40 -> 2822020.6 | E41: =E35+E36+E37+E38+E39+E40 -> 2912075.5 | F41: =F35+F36+F37+F38+F39+F40 -> 2662269.1 | G41: =G35+G36+G37+G38+G39+G40 -> 2784638 | H41: =H35+H36+H37+H38+H39+H40 -> 2667951 | I41: =I35+I36+I37+I38+I39+I40 -> 2634613 | J41: =J35+J36+J37+J38+J39+J40 -> 2664553.2 | K41: =K35+K36+K37+K38+K39+K40 -> 2753799.7 | ... O41: =O35+O36+O37+O38+O39+O40 -> 2851025.3
A42: ppe_gross | B42: Fixed assets at cost | C42: =Hist_Balances!$AJ$14+Hist_Balances!$AJ$15+Hist_Balances!$AJ$16 -> 922000 | D42: =C42+Drivers!D15 -> 922000 | E42: =D42+Drivers!E15 -> 922000 | F42: =E42+Drivers!F15 -> 922000 | G42: =F42+Drivers!G15 -> 922000 | H42: =G42+Drivers!H15 -> 922000 | I42: =H42+Drivers!I15 -> 962000 | J42: =I42+Drivers!J15 -> 962000 | K42: =J42+Drivers!K15 -> 962000 | ... O42: =N42+Drivers!O15 -> 962000
A43: acc_dep | B43: Accumulated depreciation | C43: =Hist_Balances!$AJ$17 -> -670785.63 | D43: =C43+D27 -> -676798.72 | E43: =D43+E27 -> -682811.81 | F43: =E43+F27 -> -688824.9 | G43: =F43+G27 -> -694837.99 | H43: =G43+H27 -> -700851.08 | I43: =H43+I27 -> -706864.17 | J43: =I43+J27 -> -713353.45 | K43: =J43+K27 -> -719842.73 | ... O43: =N43+O27 -> -745799.85
...

Sheet Scenario_Results
A1: ⚠ SIMULATED FINANCIAL INFORMATION - synthetic demonstration accounts of a fictional retailer, not actual company records. Synthetic data generated for a VisiVault Analytics proof of concept (seed 20240102). Fictional retailer.
A2: Scenario comparison and sensitivity analysis (values computed by the Python engine at build time)
A3: The Forecast sheet recalculates live for the scenario selected on Assumptions; this sheet stores all three for comparison.
B5: Conservative | C5: Base | D5: Optimistic
A6: bookings | B6: 9571064.4 | C6: 10401988 | D6: 11201333
A7: net_revenue | B7: 9249136.2 | C7: 10054077 | D7: 10844374
A8: gross_profit | B8: 3879628.2 | C8: 4322091.8 | D8: 4885303.6
A9: gross_margin_pct | B9: 41.945844 | C9: 42.988451 | D9: 45.049198
A10: ebitda | B10: 380793.27 | C10: 797353.35 | D10: 1291546.7
A11: net_income | B11: 258375.25 | C11: 611286.36 | D11: 991815.22
A12: net_margin_pct | B12: 2.7935068 | C12: 6.0799851 | D12: 9.1458963
A13: cfo | B13: 132898.88 | C13: 603439.42 | D13: 1174585
A14: closing_cash | B14: 1381068.6 | C14: 1812609.1 | D14: 2337754.7
A15: min_cash | B15: 1296703.6 | C15: 1520292.6 | D15: 1799169.9
A16: peak_revolver | B16: 0 | C16: 0 | D16: 0
A17: closing_deposits | B17: 529230.11 | C17: 547192.11 | D17: 559107.11
... A23: max_abs_cash_check | B23: 1.1641532e-10 | C23: 1.0186341e-10 | D23: 2.1827873e-10
A26: Sensitivity analysis (one driver at a time vs Base)
A27: scenario | B27: driver | C27: value | D27: delta_net_revenue | E27: delta_gross_profit | F27: delta_net_income | G27: delta_cfo | H27: delta_closing_cash | I27: delta_working_capital | J27: net_income | K27: closing_cash
A28: 5% sales volume increase | B28: volume_change | C28: 0.05 | D28: 455503 | E28: 195813.68 | F28: 117278.96 | G28: 160107.15 | H28: 151107.15 | I28: 108278.96 | J28: 728565.33 | K28: 1963716.3
A29: 2-pt gross-margin improvement | B29: margin_pts | C29: 0.02 | D29: 0 | E29: 209649.06 | F29: 161429.78 | G29: 208644.21 | H29: 188644.21 | I29: 141429.78 | J29: 772716.14 | K29: 2001253.3
A30: 10% reduction in slow-moving inventory | B30: slow_reduction | C30: 0.1 | D30: 0 | E30: -2653.3198 | F30: -2043.0562 | G30: 11223.543 | H30: 12223.543 | I30: -1043.0562 | J30: 609243.31 | K30: 1824832.7
A31: 15% reduction in supplier delays | B31: delay_reduction | C31: 0.15 | D31: 83996.222 | E31: 36108.675 | F31: 26256.98 | G31: 15339.965 | H31: 4339.965 | I31: 15256.98 | J31: 637543.34 | K31: 1816949.1
A32: 10% increase in design-consultation conversion | B32: consult_conv_change | C32: 0.1 | D32: 232917.46 | E32: 100127.61 | F32: 59969.569 | G32: 81869.387 | H32: 77869.387 | I32: 55969.569 | J32: 671255.93 | K32: 1890478.5
A33: Supplier terms +10 days | B33: dpo_change_days | C33: 10 | D33: 0 | E33: 0 | F33: 0 | G33: 136634.57 | H33: 136634.57 | I33: 0 | J33: 611286.36 | K33: 1949243.7
A34: Supplier terms -10 days | B34: dpo_change_days | C34: -10 | D34: 0 | E34: 0 | F34: 0 | G34: -136634.57 | H34: -136634.57 | I34: 2.3283064e-10 | J34: 611286.36 | K34: 1675974.6
A35: Operating expenses -5% | B35: opex_change | C35: -0.05 | D35: 0 | E35: 0 | F35: 88950.849 | G35: 105777.47 | H35: 94777.47 | I35: 77950.849 | J35: 700237.21 | K35: 1907386.6
A36: Operating expenses +5% | B36: opex_change | C36: 0.05 | D36: 0 | E36: 0 | F36: -93175.443 | G36: -105777.47 | H36: -94777.47 | I36: -82175.443 | J36: 518110.92 | K36: 1717831.7
A37: Promotional discounts +2 pts | B37: discount_change | C37: 0.02 | D37: -193588.94 | E37: -83220.887 | F37: -50191.832 | G37: -68045.599 | H37: -64045.599 | I37: -46191.832 | J37: 561094.53 | K37: 1748563.5
A38: Promotional discounts -2 pts | B38: discount_change | C38: -0.02 | D38: 193588.94 | E38: 83220.887 | F38: 49843.603 | G38: 68045.599 | H38: 64045.599 | I38: 45843.603 | J38: 661129.97 | K38: 1876654.7
A39: Prime rate +100 bps | B39: rate_change | C39: 0.01 | D39: 0 | E39: 0 | F39: -761.97818 | G39: -905.72795 | H39: -905.72795 | I39: -761.97818 | J39: 610524.39 | K39: 1811703.4
A42: LIVE: active scenario (formulas on the Forecast sheet)
A43: Net revenue | B43: =SUM(Forecast!D13:O13) -> 10054077
A44: Net income | B44: =SUM(Forecast!D32:O32) -> 611286.36
A45: Closing cash Sep-2027 | B45: =Forecast!O35 -> 1812609.1
A46: Minimum month-end cash | B46: =MIN(Forecast!D35:O35) -> 1520292.6
A47: Peak revolver | B47: =MAX(0,MAX(Forecast!D52:O52)) -> 0
A48: Customer deposits Sep-2027 | B48: =Forecast!O48 -> 547192.11
A49: Max |balance-sheet check| | B49: =MAX(ABS(MIN(Forecast!D81:O81)),ABS(MAX(Forecast!D81:O81))) -> 0

Sheet Checks
A1: ⚠ SIMULATED FINANCIAL INFORMATION - synthetic demonstration accounts of a fictional retailer, not actual company records. Synthetic data generated for a VisiVault Analytics proof of concept (seed 20240102). Fictional retailer.
A2: Model integrity checks (live formulas - every value must be 0 / TRUE)
A5: Check | B5: Value | C5: Pass?
A6: Trial balance: max |sum of account balances| (Dec-2023 to Sep-2026) | B6: =MAX(ABS(MIN(Hist_Balances!$C$66:$AJ$66)),ABS(MAX(Hist_Balances!$C$66:$AJ$66))) -> 0 | C6: =ABS(B6)<0.01 -> TRUE
A7: Historical balance sheet: max |assets - liabilities - equity| | B7: =MAX(ABS(MIN(Hist_BS!C33:AI33)),ABS(MAX(Hist_BS!C33:AI33))) -> 0 | C7: =ABS(B7)<0.01 -> TRUE
A8: Historical cash flow: max |closing cash - balance-sheet cash| | B8: =MAX(ABS(MIN(Hist_CF!C25:AI25)),ABS(MAX(Hist_CF!C25:AI25))) -> 0 | C8: =ABS(B8)<0.01 -> TRUE
A9: Forecast balance sheet: max |assets - liabilities - equity| | B9: =MAX(ABS(MIN(Forecast!D81:O81)),ABS(MAX(Forecast!D81:O81))) -> 0 | C9: =ABS(B9)<0.01 -> TRUE
A10: Forecast cash flow: max |closing cash - balance-sheet cash| | B10: =MAX(ABS(MIN(Forecast!D82:O82)),ABS(MAX(Forecast!D82:O82))) -> 1.1641532e-10 | C10: =ABS(B10)<0.01 -> TRUE
A11: Forecast opening cash = historical closing cash (Sep-2026) | B11: =ROUND(Forecast!C35-Hist_BS!AI6,2) -> 0 | C11: =ABS(B11)<0.01 -> TRUE
A12: ALL CHECKS PASS | C12: =AND(C6:C11) -> TRUE

Sheet Hist_IS
A1: ⚠ SIMULATED FINANCIAL INFORMATION - synthetic demonstration accounts of a fictional retailer, not actual company records. Synthetic data generated for a VisiVault Analytics proof of concept (seed 20240102). Fictional retailer.
A2: Historical income statements - illustrative Calgary management accounts (CAD)
A3: Monthly values from the general ledger; subtotal rows are live formulas. FY columns sum the months.
A5: Line | B5: Key | C5: 2024-01 | D5: 2024-02 | E5: 2024-03 | F5: 2024-04 | G5: 2024-05 | H5: 2024-06 | I5: 2024-07 | J5: 2024-08 | K5: 2024-09 | L5: 2024-10 | M5: 2024-11 | N5: 2024-12 | O5: 2025-01 | P5: 2025-02 | Q5: 2025-03 | R5: 2025-04 | S5: 2025-05 | T5: 2025-06 | U5: 2025-07 | V5: 2025-08 | W5: 2025-09 | X5: 2025-10 | Y5: 2025-11 | Z5: 2025-12 | AA5: 2026-01 | AB5: 2026-02 | AC5: 2026-03 | AD5: 2026-04 | AE5: 2026-05 | AF5: 2026-06 | AG5: 2026-07 | AH5: 2026-08 | AI5: 2026-09 | AJ5: FY2024 | AK5: FY2025 | AL5: YTD Sep-2026
A6: Sofas & sectionals | B6: sales_sofas | C6: 309788.86 | D6: 221836.01 | E6: 211177.58 | F6: 179993.87 | G6: 221197.61 | H6: 261826.19 | I6: 250254.41 | J6: 234255.93 | K6: 224786.22 | L6: 232668.23 | M6: 278883.33 | N6: 237041.04 | O6: 311517.01 | P6: 230123.16 | Q6: 320540.76 | R6: 219338 | S6: 283717.06 | T6: 255942.51 | U6: 237331.46 | V6: 233425.01 | W6: 239149.89 | X6: 251243.25 | Y6: 251511.27 | Z6: 222952.42 | AA6: 382635.13 | AB6: 238394.6 | AC6: 306598.09 | AD6: 282109.94 | AE6: 342796.83 | AF6: 349744.27 | AG6: 268523.05 | AH6: 268342.42 | AI6: 304372.57 | AJ6: =SUM(C6:N6) -> 2863709.3 | AK6: =SUM(O6:Z6) -> 3056791.8 | AL6: =SUM(AA6:AI6) -> 2743516.9
A7: Bedroom | B7: sales_bedroom | C7: 202461.72 | D7: 124724.28 | E7: 164028.43 | F7: 130732.01 | G7: 163144.83 | H7: 89622.65 | I7: 162818.99 | J7: 146442.11 | K7: 160021.9 | L7: 105099.46 | M7: 180390.69 | N7: 144954.95 | O7: 166279.98 | P7: 120703.82 | Q7: 173432.57 | R7: 153781.76 | S7: 159793.05 | T7: 146408.33 | U7: 148461.42 | V7: 141766.62 | W7: 115732.74 | X7: 145507.28 | Y7: 167443.39 | Z7: 135248.86 | AA7: 160300.13 | AB7: 141425.48 | AC7: 167711.98 | AD7: 173247.75 | AE7: 157879.78 | AF7: 182181.36 | AG7: 194951.69 | AH7: 131862.34 | AI7: 134635.14 | AJ7: =SUM(C7:N7) -> 1774442 | AK7: =SUM(O7:Z7) -> 1774559.8 | AL7: =SUM(AA7:AI7) -> 1444195.6
A8: Mattresses & bases | B8: sales_mattress | C8: 102730.95 | D8: 40496.93 | E8: 68452.9 | F8: 62719.94 | G8: 73833.97 | H8: 49329.99 | I8: 82338.9 | J8: 71884.97 | K8: 52988.95 | L8: 67823.95 | M8: 87026.93 | N8: 71183.97 | O8: 64050.91 | P8: 59508.89 | Q8: 92895.95 | R8: 69986.97 | S8: 99447.97 | T8: 85939.95 | U8: 83440.96 | V8: 58987.96 | W8: 62810.89 | X8: 71887.91 | Y8: 106833.89 | Z8: 83404.95 | AA8: 66318.93 | AB8: 87747.96 | AC8: 83314.93 | AD8: 85870.9 | AE8: 89013.88 | AF8: 95212.95 | AG8: 84845.94 | AH8: 61900.98 | AI8: 51728.91 | AJ8: =SUM(C8:N8) -> 830812.35 | AK8: =SUM(O8:Z8) -> 939197.2 | AL8: =SUM(AA8:AI8) -> 705955.38
A9: Dining | B9: sales_dining | C9: 188416 | D9: 172463 | E9: 131705 | F9: 168550 | G9: 165002 | H9: 209645 | I9: 175485 | J9: 146229 | K9: 215113 | L9: 157047 | M9: 192362 | N9: 196088 | O9: 174917 | P9: 180812 | Q9: 163441 | R9: 205647 | S9: 215723 | T9: 228138 | U9: 182779 | V9: 232108 | W9: 207194 | X9: 228866 | Y9: 227417 | Z9: 226803 | AA9: 217500 | AB9: 140112 | AC9: 208114 | AD9: 194416 | AE9: 188175 | AF9: 189131 | AG9: 211309 | AH9: 213516 | AI9: 209749 | AJ9: =SUM(C9:N9) -> 2118105 | AK9: =SUM(O9:Z9) -> 2473845 | AL9: =SUM(AA9:AI9) -> 1772022
A10: Living & occasional | B10: sales_living | C10: 105983.94 | D10: 83380.85 | E10: 94654 | F10: 74519 | G10: 98130 | H10: 92435.92 | I10: 99732.79 | J10: 91182.66 | K10: 91383.71 | L10: 95628.79 | M10: 111548 | N10: 84086.85 | O10: 99269.8 | P10: 88328.85 | Q10: 107858.16 | R10: 91859.98 | S10: 148697.45 | T10: 96007.72 | U10: 110555.85 | V10: 99735.92 | W10: 109951.11 | X10: 92092.49 | Y10: 126381.92 | Z10: 90268.64 | AA10: 131928.94 | AB10: 108885.64 | AC10: 104269.7 | AD10: 102870.12 | AE10: 141054.31 | AF10: 118100.79 | AG10: 94037.04 | AH10: 101747.96 | AI10: 127892 | AJ10: =SUM(C10:N10) -> 1122666.5 | AK10: =SUM(O10:Z10) -> 1261007.9 | AL10: =SUM(AA10:AI10) -> 1030786.5
A11: Home office | B11: sales_office | C11: 6847 | D11: 6280 | E11: 5097.43 | F11: 7682.43 | G11: 8204 | H11: 9282 | I11: 0 | J11: 6892 | K11: 4216 | L11: 3694 | M11: 2837 | N11: 6915 | O11: 9997 | P11: 2745 | Q11: 1978 | R11: 5435 | S11: 7304 | T11: 10073 | U11: 9214 | V11: 7825 | W11: 5006 | X11: 8775 | Y11: 12856 | Z11: 16299 | AA11: 7175 | AB11: 7656 | AC11: 3797 | AD11: 3458 | AE11: 11241 | AF11: 3627 | AG11: 6756 | AH11: 7176 | AI11: 4576 | AJ11: =SUM(C11:N11) -> 67946.86 | AK11: =SUM(O11:Z11) -> 97507 | AL11: =SUM(AA11:AI11) -> 55462
A12: Décor & lighting | B12: sales_decor | C12: 61715.88 | D12: 37341.85 | E12: 41058.95 | F12: 41416.89 | G12: 48157.9 | H12: 51925.91 | I12: 57994.9 | J12: 45348.9 | K12: 43489.9 | L12: 41857.91 | M12: 55920.9 | N12: 58075.88 | O12: 53799.88 | P12: 49360.88 | Q12: 48178.86 | R12: 56593.89 | S12: 54672.88 | T12: 45865.89 | U12: 51110.88 | V12: 50791.82 | W12: 47875.9 | X12: 48023.86 | Y12: 53576.93 | Z12: 39443.88 | AA12: 73875.79 | AB12: 56179.84 | AC12: 53901.94 | AD12: 51354.9 | AE12: 63379.85 | AF12: 65740.84 | AG12: 52368.88 | AH12: 59206.94 | AI12: 56283.89 | AJ12: =SUM(C12:N12) -> 584305.77 | AK12: =SUM(O12:Z12) -> 599295.55 | AL12: =SUM(AA12:AI12) -> 532292.87
A13: Gross furniture sales | B13: gross_sales | C13: =C6+C7+C8+C9+C10+C11+C12 -> 977944.35 | D13: =D6+D7+D8+D9+D10+D11+D12 -> 686522.92 | E13: =E6+E7+E8+E9+E10+E11+E12 -> 716174.29 | F13: =F6+F7+F8+F9+F10+F11+F12 -> 665614.14 | G13: =G6+G7+G8+G9+G10+G11+G12 -> 777670.31 | H13: =H6+H7+H8+H9+H10+H11+H12 -> 764067.66 | I13: =I6+I7+I8+I9+I10+I11+I12 -> 828624.99 | J13: =J6+J7+J8+J9+J10+J11+J12 -> 742235.57 | ... AI13: =AI6+AI7+AI8+AI9+AI10+AI11+AI12 -> 889237.51 | AJ13: =SUM(C13:N13) -> 9361987.8 | AK13: =SUM(O13:Z13) -> 10202204 | AL13: =SUM(AA13:AI13) -> 8284231.3
A14: Less: discounts & promotional allowances | B14: discounts | C14: -82728.93 | D14: -47242.99 | E14: -38498.14 | F14: -33764.15 | G14: -37118.45 | H14: -30072.04 | I14: -46347.95 | J14: -34656.44 | K14: -50533.93 | L14: -37722.95 | M14: -45204.36 | N14: -69175.8 | O14: -80981.37 | P14: -52999.26 | Q14: -52709.63 | R14: -40124.98 | S14: -48311.51 | T14: -44425.65 | U14: -41884.74 | V14: -39614.71 | W14: -42014.74 | X14: -39584.22 | Y14: -46274.46 | Z14: -62347.02 | AA14: -93884.84 | AB14: -55035.31 | AC14: -52075.78 | AD14: -47743.67 | AE14: -51258.71 | AF14: -50707.64 | AG14: -54658.58 | AH14: -38608.77 | AI14: -48480.95 | AJ14: =SUM(C14:N14) -> -553066.13 | AK14: =SUM(O14:Z14) -> -591272.29 | AL14: =SUM(AA14:AI14) -> -492454.25
A15: Less: sales returns | B15: returns | C15: -7165 | D15: -12295 | E15: -12312 | F15: -12828 | G15: -10321 | H15: -10986 | I15: -7371 | J15: -9013 | K15: -7930.75 | L15: -9672 | M15: -25178 | N15: -8322 | O15: -3188 | P15: -1666 | Q15: -2806 | R15: -9003 | S15: -11002 | T15: -6545 | U15: -6924 | V15: -998 | W15: -8467 | X15: -8861 | Y15: -10115 | Z15: -5454 | AA15: 0 | AB15: -1549 | AC15: -8612.99 | AD15: -2698 | AE15: -8825.75 | AF15: -14067 | AG15: -3411 | AH15: -16893 | AI15: -14418 | AJ15: =SUM(C15:N15) -> -133393.75 | AK15: =SUM(O15:Z15) -> -75029 | AL15: =SUM(AA15:AI15) -> -70474.74
A16: Net furniture sales | B16: net_sales | C16: =C13+C14+C15 -> 888050.42 | D16: =D13+D14+D15 -> 626984.93 | E16: =E13+E14+E15 -> 665364.15 | F16: =F13+F14+F15 -> 619021.99 | G16: =G13+G14+G15 -> 730230.86 | H16: =H13+H14+H15 -> 723009.62 | I16: =I13+I14+I15 -> 774906.04 | J16: =J13+J14+J15 -> 698566.13 | ... AI16: =AI13+AI14+AI15 -> 826338.56 | AJ16: =SUM(C16:N16) -> 8675527.9 | AK16: =SUM(O16:Z16) -> 9535903 | AL16: =SUM(AA16:AI16) -> 7721302.3
A17: Protection-plan commissions (agent, net) | B17: plan_comm | C17: 5463.93 | D17: 5113.1 | E17: 3419.33 | F17: 2291.56 | G17: 3382.22 | H17: 3731 | I17: 3124.74 | J17: 3320.7 | K17: 3038.03 | L17: 3544.4 | M17: 4243.99 | N17: 3328.31 | O17: 3386.04 | P17: 4501.78 | Q17: 4401.79 | R17: 4886.65 | S17: 5240.55 | T17: 3444.07 | U17: 6237.67 | V17: 3534.02 | W17: 3120.67 | X17: 4947.76 | Y17: 4953.23 | Z17: 4091.09 | AA17: 4184.21 | AB17: 2422.44 | AC17: 4020.86 | AD17: 4260.89 | AE17: 5342.11 | AF17: 5157.88 | AG17: 3575.3 | AH17: 4231.93 | AI17: 4260.21 | AJ17: =SUM(C17:N17) -> 44001.31 | AK17: =SUM(O17:Z17) -> 52745.32 | AL17: =SUM(AA17:AI17) -> 37455.83
A18: Restocking fees | B18: restock_fees | C18: 1074.75 | D18: 1844.25 | E18: 1846.8 | F18: 1924.2 | G18: 1548.15 | H18: 1647.9 | I18: 1105.65 | J18: 1351.95 | K18: 1189.61 | L18: 1450.8 | M18: 3776.7 | N18: 1248.3 | O18: 478.2 | P18: 249.9 | Q18: 420.9 | R18: 1350.45 | S18: 1650.3 | T18: 981.75 | U18: 1038.6 | V18: 149.7 | W18: 1270.05 | X18: 1329.15 | Y18: 1517.25 | Z18: 818.1 | AA18: 0 | AB18: 232.35 | AC18: 1291.95 | AD18: 404.7 | AE18: 1323.86 | AF18: 2110.05 | AG18: 511.65 | AH18: 2533.95 | AI18: 2162.7 | AJ18: =SUM(C18:N18) -> 20009.06 | AK18: =SUM(O18:Z18) -> 11254.35 | AL18: =SUM(AA18:AI18) -> 10571.21
A19: Retained cancellation fees | B19: cancel_fees | C19: 2347.59 | D19: 4157.35 | E19: 2510.61 | F19: 7800.27 | G19: 3906.42 | H19: 3188.85 | I19: 1391.96 | J19: 1823.24 | K19: 611.53 | L19: 736.53 | M19: 0 | N19: 4993.23 | O19: 4423.63 | P19: 590.35 | Q19: 645.19 | R19: 4970.89 | S19: 0 | T19: 551.67 | U19: 0 | V19: 6714.66 | W19: 5163.75 | X19: 1569.97 | Y19: 3742.16 | Z19: 4547.31 | AA19: 1399.81 | AB19: 2683.72 | AC19: 2801.66 | AD19: 2812.04 | AE19: 1073.53 | AF19: 805.77 | AG19: 2421.86 | AH19: 753.21 | AI19: 941.48 | AJ19: =SUM(C19:N19) -> 33467.58 | AK19: =SUM(O19:Z19) -> 32919.58 | AL19: =SUM(AA19:AI19) -> 15693.08
A20: Total net revenue | B20: net_rev | C20: =C16+C17+C18+C19 -> 896936.69 | D20: =D16+D17+D18+D19 -> 638099.63 | E20: =E16+E17+E18+E19 -> 673140.89 | F20: =F16+F17+F18+F19 -> 631038.02 | G20: =G16+G17+G18+G19 -> 739067.65 | H20: =H16+H17+H18+H19 -> 731577.37 | I20: =I16+I17+I18+I19 -> 780528.39 | J20: =J16+J17+J18+J19 -> 705062.02 | ... AI20: =AI16+AI17+AI18+AI19 -> 833702.95 | AJ20: =SUM(C20:N20) -> 8773005.9 | AK20: =SUM(O20:Z20) -> 9632822.2 | AL20: =SUM(AA20:AI20) -> 7785022.4
A21: Cost of goods sold - merchandise | B21: cogs_merch | C21: -500305.82 | D21: -348579.54 | E21: -361291.02 | F21: -332641.15 | G21: -391845.69 | H21: -388737.05 | I21: -422202.79 | J21: -375732.69 | K21: -406850.94 | L21: -355686.24 | M21: -454400.11 | N21: -400268.67 | O21: -451878.83 | P21: -375973.14 | Q21: -468732.17 | R21: -406476.2 | S21: -492911.17 | T21: -441809.85 | U21: -418540.4 | V21: -424520.78 | W21: -401227.62 | X21: -429367.43 | Y21: -476807.05 | Z21: -413139.42 | AA21: -537695.99 | AB21: -397270.84 | AC21: -476686.1 | AD21: -460488.98 | AE21: -505092.2 | AF21: -512218.39 | AG21: -466430.8 | AH21: -426240.54 | AI21: -451765.48 | AJ21: =SUM(C21:N21) -> -4738541.7 | AK21: =SUM(O21:Z21) -> -5201384.1 | AL21: =SUM(AA21:AI21) -> -4233889.3
A22: Freight-in & supplier charges | B22: freight_in | C22: -17273.64 | D22: -15303.37 | E22: -14546.44 | F22: -15912.17 | G22: -15643.17 | H22: -14206.95 | I22: -15116.86 | J22: -18680.47 | K22: -14047.39 | L22: -15835.59 | M22: -15268.22 | N22: -19108.85 | O22: -18005.24 | P22: -16453.73 | Q22: -22178.18 | R22: -17751.12 | S22: -17698.18 | T22: -16688.77 | U22: -17004.42 | V22: -18656.42 | W22: -18515.35 | X22: -15819.31 | Y22: -18249.23 | Z22: -23461.65 | AA22: -17186.86 | AB22: -19095.25 | AC22: -23366.2 | AD22: -19210.14 | AE22: -19285.56 | AF22: -19569.13 | AG22: -17137.53 | AH22: -21125.64 | AI22: -15968.02 | AJ22: =SUM(C22:N22) -> -190943.12 | AK22: =SUM(O22:Z22) -> -220481.6 | AL22: =SUM(AA22:AI22) -> -171944.33
A23: Inventory variances, shrinkage & write-offs | B23: inv_var | C23: -3909.41 | D23: -3369 | E23: -339.45 | F23: -3109.03 | G23: -6853.91 | H23: -552.3 | I23: -3893.26 | J23: -4778.25 | K23: -5673.85 | L23: -6211.05 | M23: -2506.36 | N23: -8045.08 | O23: -4539.46 | P23: -3313.48 | Q23: -3915.85 | R23: -4782.64 | S23: -7640.2 | T23: -2255.67 | U23: -3556.69 | V23: -21.4 | W23: -6814.91 | X23: -8837.78 | Y23: -924.04 | Z23: -6448.41 | AA23: -6627.07 | AB23: -5511.26 | AC23: -2456.55 | AD23: -5496.08 | AE23: -993.38 | AF23: -6727.03 | AG23: -4095.75 | AH23: -2933.04 | AI23: -8096.9 | AJ23: =SUM(C23:N23) -> -49240.95 | AK23: =SUM(O23:Z23) -> -53050.53 | AL23: =SUM(AA23:AI23) -> -42937.06
A24: Cost of goods sold | B24: cogs | C24: =C21+C22+C23 -> -521488.87 | D24: =D21+D22+D23 -> -367251.91 | E24: =E21+E22+E23 -> -376176.91 | F24: =F21+F22+F23 -> -351662.35 | G24: =G21+G22+G23 -> -414342.77 | H24: =H21+H22+H23 -> -403496.3 | I24: =I21+I22+I23 -> -441212.91 | J24: =J21+J22+J23 -> -399191.41 | ... AI24: =AI21+AI22+AI23 -> -475830.4 | AJ24: =SUM(C24:N24) -> -4978725.8 | AK24: =SUM(O24:Z24) -> -5474916.2 | AL24: =SUM(AA24:AI24) -> -4448770.7
A25: Gross profit | B25: gross_profit | C25: =C20+C24 -> 375447.82 | D25: =D20+D24 -> 270847.72 | E25: =E20+E24 -> 296963.98 | F25: =F20+F24 -> 279375.67 | G25: =G20+G24 -> 324724.88 | H25: =H20+H24 -> 328081.07 | I25: =I20+I24 -> 339315.48 | J25: =J20+J24 -> 305870.61 | ... AI25: =AI20+AI24 -> 357872.55 | AJ25: =SUM(C25:N25) -> 3794280.1 | AK25: =SUM(O25:Z25) -> 4157906 | AL25: =SUM(AA25:AI25) -> 3336251.7
A26: Employee compensation (incl. commissions & designers) | B26: emp_comp | C26: -123747.89 | D26: -114225.96 | E26: -120999.72 | F26: -126471.44 | G26: -126795.76 | H26: -121660.36 | I26: -124959.06 | J26: -126338.93 | K26: -121145.14 | L26: -124347.01 | M26: -127133.24 | N26: -118083.22 | O26: -132297.6 | P26: -119493.58 | Q26: -130879.13 | R26: -133757.97 | S26: -135845.86 | T26: -126604.34 | U26: -127384.65 | V26: -132277.03 | W26: -133097.91 | X26: -134272.23 | Y26: -133879.26 | Z26: -129735.84 | AA26: -142946.56 | AB26: -127512.49 | AC26: -139597.94 | AD26: -134543.3 | AE26: -137660.12 | AF26: -136075.14 | AG26: -137731.68 | AH26: -137586.75 | AI26: -136172.01 | AJ26: =SUM(C26:N26) -> -1475907.7 | AK26: =SUM(O26:Z26) -> -1569525.4 | AL26: =SUM(AA26:AI26) -> -1229826
A27: Occupancy (rent, CAM & property tax, utilities) | B27: occupancy | C27: -65273.57 | D27: -64221.53 | E27: -63174.93 | F27: -61946.11 | G27: -61647.62 | H27: -60645.2 | I27: -59691.67 | J27: -59909.13 | K27: -60902.54 | L27: -62517.13 | M27: -63239.98 | N27: -64395.31 | O27: -66543.28 | P27: -65915.14 | Q27: -64872.41 | R27: -63508.33 | S27: -62994.37 | T27: -61537.26 | U27: -60923.5 | V27: -61803.17 | W27: -62476.21 | X27: -63617.82 | Y27: -64433.11 | Z27: -65703.62 | AA27: -67790.22 | AB27: -66684.52 | AC27: -65994.63 | AD27: -64996.87 | AE27: -64551.13 | AF27: -62985.42 | AG27: -62569.29 | AH27: -63283.94 | AI27: -64084.51 | AJ27: =SUM(C27:N27) -> -747564.72 | AK27: =SUM(O27:Z27) -> -764328.22 | AL27: =SUM(AA27:AI27) -> -582940.53
A28: Marketing & advertising | B28: marketing | C28: -48733.99 | D28: -32821.36 | E28: -23423.82 | F28: -35604.52 | G28: -43873.62 | H28: -34223.34 | I28: -28254.25 | J28: -31100.28 | K28: -46297.43 | L28: -46991.81 | M28: -43140.87 | N28: -39272.49 | O28: -39436.99 | P28: -40341.65 | Q28: -25322.5 | R28: -50419.79 | S28: -48282.39 | T28: -43261.63 | U28: -30350.12 | V28: -30307.3 | W28: -47609.28 | X28: -47533.51 | Y28: -48842.69 | Z28: -46506.29 | AA28: -47859.98 | AB28: -48205.19 | AC28: -26707.68 | AD28: -54305.57 | AE28: -47808.85 | AF28: -40697.15 | AG28: -32883.08 | AH28: -37623.38 | AI28: -45007.95 | AJ28: =SUM(C28:N28) -> -453737.78 | AK28: =SUM(O28:Z28) -> -498214.14 | AL28: =SUM(AA28:AI28) -> -381098.83
A29: General & administrative (insurance, professional, IT) | B29: g_and_a | C29: -16293.28 | D29: -16156.75 | E29: -16495.13 | F29: -16007.81 | G29: -16547.12 | H29: -15219.28 | I29: -16978.11 | J29: -16107.1 | K29: -16081.98 | L29: -16782.96 | M29: -16585.39 | N29: -16780.64 | O29: -16310.1 | P29: -17095.88 | Q29: -17111.71 | R29: -17109.07 | S29: -17246 | T29: -16470.7 | U29: -16974.6 | V29: -16321.72 | W29: -16650.56 | X29: -16561.76 | Y29: -15830.91 | Z29: -16735.24 | AA29: -16573.43 | AB29: -16763.33 | AC29: -16563.96 | AD29: -16678.67 | AE29: -16572.77 | AF29: -17167.01 | AG29: -17604.01 | AH29: -17464.29 | AI29: -17975.18 | AJ29: =SUM(C29:N29) -> -196035.55 | AK29: =SUM(O29:Z29) -> -200418.25 | AL29: =SUM(AA29:AI29) -> -153362.65
A30: Warehouse, fulfilment & design-consult costs | B30: warehouse | C30: -6489.04 | D30: -5852.08 | E30: -6681.79 | F30: -6002.37 | G30: -7201.6 | H30: -5732.8 | I30: -5641.13 | J30: -5622.62 | K30: -6056.78 | L30: -6449.78 | M30: -6729.74 | N30: -6903.8 | O30: -7325.9 | P30: -6191.32 | Q30: -6601.13 | R30: -6733.02 | S30: -6535.64 | T30: -6610.3 | U30: -6450.21 | V30: -6886.73 | W30: -6912.28 | X30: -7025.45 | Y30: -7034.29 | Z30: -6534.2 | AA30: -7659.74 | AB30: -7019.83 | AC30: -6365.9 | AD30: -6763.94 | AE30: -6858.05 | AF30: -6599.61 | AG30: -6564.53 | AH30: -6999.28 | AI30: -7893.19 | AJ30: =SUM(C30:N30) -> -75363.53 | AK30: =SUM(O30:Z30) -> -80840.47 | AL30: =SUM(AA30:AI30) -> -62724.07
A31: Card & financing-partner fees | B31: fees | C31: -20003.86 | D31: -15003.29 | E31: -15131.27 | F31: -14624.1 | G31: -15118.41 | H31: -15326.03 | I31: -16458.45 | J31: -18280.75 | K31: -18902.79 | L31: -14626.79 | M31: -20499.28 | N31: -15489.71 | O31: -19574.54 | P31: -16342.69 | Q31: -20498.43 | R31: -19611.45 | S31: -21544.89 | T31: -18597.14 | U31: -16899.32 | V31: -17665.98 | W31: -17559.66 | X31: -19946.35 | Y31: -21487.29 | Z31: -19273.34 | AA31: -22543.56 | AB31: -15751.79 | AC31: -21599.94 | AD31: -20414.57 | AE31: -22534.95 | AF31: -20158.71 | AG31: -20624.37 | AH31: -18151.28 | AI31: -22556.2 | AJ31: =SUM(C31:N31) -> -199464.73 | AK31: =SUM(O31:Z31) -> -229001.08 | AL31: =SUM(AA31:AI31) -> -184335.37
A32: Operating expenses (before depreciation) | B32: opex | C32: =C26+C27+C28+C29+C30+C31 -> -280541.63 | D32: =D26+D27+D28+D29+D30+D31 -> -248280.97 | E32: =E26+E27+E28+E29+E30+E31 -> -245906.66 | F32: =F26+F27+F28+F29+F30+F31 -> -260656.35 | G32: =G26+G27+G28+G29+G30+G31 -> -271184.13 | H32: =H26+H27+H28+H29+H30+H31 -> -252807.01 | I32: =I26+I27+I28+I29+I30+I31 -> -251982.67 | J32: =J26+J27+J28+J29+J30+J31 -> -257358.81 | ... AI32: =AI26+AI27+AI28+AI29+AI30+AI31 -> -293689.04 | AJ32: =SUM(C32:N32) -> -3148074 | AK32: =SUM(O32:Z32) -> -3342327.6 | AL32: =SUM(AA32:AI32) -> -2594287.4
A33: EBITDA | B33: ebitda | C33: =C25+C32 -> 94906.19 | D33: =D25+D32 -> 22566.75 | E33: =E25+E32 -> 51057.32 | F33: =F25+F32 -> 18719.32 | G33: =G25+G32 -> 53540.75 | H33: =H25+H32 -> 75274.06 | I33: =I25+I32 -> 87332.81 | J33: =J25+J32 -> 48511.8 | ... AI33: =AI25+AI32 -> 64183.51 | AJ33: =SUM(C33:N33) -> 646206.04 | AK33: =SUM(O33:Z33) -> 815578.47 | AL33: =SUM(AA33:AI33) -> 741964.28
A34: Depreciation | B34: da | C34: -7892.86 | D34: -7892.86 | E34: -7892.86 | F34: -7892.86 | G34: -7892.86 | H34: -8601.19 | I34: -8601.19 | J34: -8601.19 | K34: -8601.19 | L34: -8601.19 | M34: -8601.19 | N34: -8601.19 | O34: -8601.19 | P34: -8601.19 | Q34: -8601.19 | R34: -9172.62 | S34: -9172.62 | T34: -9172.62 | U34: -9172.62 | V34: -9172.62 | W34: -9172.62 | X34: -10172.62 | Y34: -10172.62 | Z34: -10172.62 | AA34: -10172.62 | AB34: -10172.62 | AC34: -8172.53 | AD34: -7505.95 | AE34: -7739.28 | AF34: -7739.28 | AG34: -6227.39 | AH34: -6013.09 | AI34: -6013.09 | AJ34: =SUM(C34:N34) -> -99672.63 | AK34: =SUM(O34:Z34) -> -111357.15 | AL34: =SUM(AA34:AI34) -> -69755.85
A35: Operating income (EBIT) | B35: ebit | C35: =C33+C34 -> 87013.33 | D35: =D33+D34 -> 14673.89 | E35: =E33+E34 -> 43164.46 | F35: =F33+F34 -> 10826.46 | G35: =G33+G34 -> 45647.89 | H35: =H33+H34 -> 66672.87 | I35: =I33+I34 -> 78731.62 | J35: =J33+J34 -> 39910.61 | ... AI35: =AI33+AI34 -> 58170.42 | AJ35: =SUM(C35:N35) -> 546533.41 | AK35: =SUM(O35:Z35) -> 704221.32 | AL35: =SUM(AA35:AI35) -> 672208.43
A36: Interest expense | B36: interest | C36: -3833.33 | D36: -3753.47 | E36: -3673.61 | F36: -3593.75 | G36: -3513.89 | H36: -3340.71 | I36: -3171.87 | J36: -3096.35 | K36: -2934.03 | L36: -2691.41 | M36: -2622.4 | N36: -2392.79 | O36: -2250 | P36: -2187.5 | Q36: -2051.22 | R36: -1990.89 | S36: -1930.56 | T36: -1870.23 | U36: -1809.9 | V36: -1749.57 | W36: -1628.47 | X36: -1511.72 | Y36: -1455.73 | Z36: -1399.74 | AA36: -1343.75 | AB36: -1287.76 | AC36: -1231.77 | AD36: -1175.78 | AE36: -1119.79 | AF36: -1063.8 | AG36: -1007.81 | AH36: -951.82 | AI36: -895.83 | AJ36: =SUM(C36:N36) -> -38617.61 | AK36: =SUM(O36:Z36) -> -21835.53 | AL36: =SUM(AA36:AI36) -> -10078.11
A37: Income before tax | B37: pbt | C37: =C35+C36 -> 83180 | D37: =D35+D36 -> 10920.42 | E37: =E35+E36 -> 39490.85 | F37: =F35+F36 -> 7232.71 | G37: =G35+G36 -> 42134 | H37: =H35+H36 -> 63332.16 | I37: =I35+I36 -> 75559.75 | J37: =J35+J36 -> 36814.26 | ... AI37: =AI35+AI36 -> 57274.59 | AJ37: =SUM(C37:N37) -> 507915.8 | AK37: =SUM(O37:Z37) -> 682385.79 | AL37: =SUM(AA37:AI37) -> 662130.32
A38: Income taxes | B38: tax | C38: -9149.8 | D38: -1201.25 | E38: -4343.99 | F38: -795.6 | G38: -4634.74 | H38: -6966.54 | I38: -8311.57 | J38: -4049.57 | K38: -3396.81 | L38: -155.67 | M38: -9446.84 | N38: -4368.25 | O38: -4090.56 | P38: -1138.51 | Q38: -9626.5 | R38: -3675.05 | S38: -10464.39 | T38: -8525.41 | U38: -7952.42 | V38: -8254.76 | W38: -4391.45 | X38: -11760.24 | Y38: -23167.29 | Z38: -3902.15 | AA38: -8033.67 | AB38: -1526.89 | AC38: -9502.91 | AD38: -6466.21 | AE38: -12207.76 | AF38: -12764.03 | AG38: -15414.06 | AH38: -13201.29 | AI38: -13173.15 | AJ38: =SUM(C38:N38) -> -56820.63 | AK38: =SUM(O38:Z38) -> -96948.73 | AL38: =SUM(AA38:AI38) -> -92289.97
A39: Net income | B39: net_income | C39: =C37+C38 -> 74030.2 | D39: =D37+D38 -> 9719.17 | E39: =E37+E38 -> 35146.86 | F39: =F37+F38 -> 6437.11 | G39: =G37+G38 -> 37499.26 | H39: =H37+H38 -> 56365.62 | I39: =I37+I38 -> 67248.18 | J39: =J37+J38 -> 32764.69 | ... AI39: =AI37+AI38 -> 44101.44 | AJ39: =SUM(C39:N39) -> 451095.17 | AK39: =SUM(O39:Z39) -> 585437.06 | AL39: =SUM(AA39:AI39) -> 569840.35

Sheet Hist_BS
A1: ⚠ SIMULATED FINANCIAL INFORMATION - synthetic demonstration accounts of a fictional retailer, not actual company records. Synthetic data generated for a VisiVault Analytics proof of concept (seed 20240102). Fictional retailer.
A2: Historical balance sheets - month end (CAD)
A3: Monthly values from the general ledger; subtotal rows are live formulas. FY columns sum the months.
A5: Line | B5: Key | C5: 2024-01 | D5: 2024-02 | E5: 2024-03 | F5: 2024-04 | G5: 2024-05 | H5: 2024-06 | I5: 2024-07 | J5: 2024-08 | K5: 2024-09 | L5: 2024-10 | M5: 2024-11 | N5: 2024-12 | O5: 2025-01 | P5: 2025-02 | Q5: 2025-03 | R5: 2025-04 | S5: 2025-05 | T5: 2025-06 | U5: 2025-07 | V5: 2025-08 | W5: 2025-09 | X5: 2025-10 | Y5: 2025-11 | Z5: 2025-12 | AA5: 2026-01 | AB5: 2026-02 | AC5: 2026-03 | AD5: 2026-04 | AE5: 2026-05 | AF5: 2026-06 | AG5: 2026-07 | AH5: 2026-08 | AI5: 2026-09 | AJ5: FY2024 | AK5: FY2025 | AL5: YTD Sep-2026
A6: Cash | B6: cash | C6: 721261.96 | D6: 627056.48 | E6: 578379.09 | F6: 605752.73 | G6: 633995.94 | H6: 673995.68 | I6: 798770.17 | J6: 880647.19 | K6: 929953.29 | L6: 933387.74 | M6: 1110369.2 | N6: 943167.72 | O6: 984564.19 | P6: 953065.09 | Q6: 943349.26 | R6: 956091.26 | S6: 1088287.5 | T6: 1124586.6 | U6: 1166259.6 | V6: 1239555.2 | W6: 1286516.9 | X6: 1351939.1 | Y6: 1692993.3 | Z6: 1370391.7 | AA6: 1397855.4 | AB6: 1391534.6 | AC6: 1416950.8 | AD6: 1392544.9 | AE6: 1489089.3 | AF6: 1592233.3 | AG6: 1616043.5 | AH6: 1655741.1 | AI6: 1722169.8 | AJ6: =N6 -> 943167.72 | AK6: =Z6 -> 1370391.7 | AL6: =AI6 -> 1722169.8
A7: Receivables (card, financing partner, trade) | B7: ar | C7: 71191.38 | D7: 54133.58 | E7: 59359.11 | F7: 73101 | G7: 54350.02 | H7: 61791.69 | I7: 68793.96 | J7: 79332.42 | K7: 71052.52 | L7: 79597.49 | M7: 135301.65 | N7: 85555.56 | O7: 100039.11 | P7: 86374.15 | Q7: 131691.29 | R7: 59535.06 | S7: 113278.15 | T7: 93097.11 | U7: 77288.16 | V7: 108253.97 | W7: 118061.85 | X7: 111355.87 | Y7: 70621.18 | Z7: 83405.43 | AA7: 119005.64 | AB7: 108744.95 | AC7: 102308.91 | AD7: 60761.61 | AE7: 72918.09 | AF7: 74983.18 | AG7: 72990.93 | AH7: 108857.88 | AI7: 73595.1 | AJ7: =N7 -> 85555.56 | AK7: =Z7 -> 83405.43 | AL7: =AI7 -> 73595.1
A8: Inventory - stocked merchandise | B8: inv_stock | C8: 651832.59 | D8: 706451.19 | E8: 711753.46 | F8: 715171.42 | G8: 668829.25 | H8: 650325.65 | I8: 629786.02 | J8: 674277.26 | K8: 610286.83 | L8: 606611.44 | M8: 524205.39 | N8: 574624.47 | O8: 493836.59 | P8: 536462.45 | Q8: 579102.47 | R8: 585192.04 | S8: 531962.23 | T8: 523465.7 | U8: 535828.72 | V8: 568502.81 | W8: 552649.75 | X8: 487615.27 | Y8: 426041.41 | Z8: 521690.17 | AA8: 406070.59 | AB8: 476623.64 | AC8: 518941.52 | AD8: 508618.6 | AE8: 515565.92 | AF8: 524688.74 | AG8: 493648.02 | AH8: 555387.46 | AI8: 505080.18 | AJ8: =N8 -> 574624.47 | AK8: =Z8 -> 521690.17 | AL8: =AI8 -> 505080.18
A9: Inventory - allocated to customer orders | B9: inv_alloc | C9: 331461.21 | D9: 296506.12 | E9: 282554.34 | F9: 301602.39 | G9: 325644.35 | H9: 293731.38 | I9: 266097.5 | J9: 284554.53 | K9: 281715.31 | L9: 315499.97 | M9: 315587.61 | N9: 291769.67 | O9: 328738.06 | P9: 302607.97 | Q9: 327740.65 | R9: 337975.85 | S9: 331542.68 | T9: 301436.91 | U9: 286624.09 | V9: 262169.11 | W9: 299425.44 | X9: 306337.94 | Y9: 327870.47 | Z9: 363035.59 | AA9: 350632.59 | AB9: 335230.1 | AC9: 356345.26 | AD9: 371942.58 | AE9: 336003.59 | AF9: 295114.6 | AG9: 270991.28 | AH9: 297570.67 | AI9: 279846.23 | AJ9: =N9 -> 291769.67 | AK9: =Z9 -> 363035.59 | AL9: =AI9 -> 279846.23
